Workbook

Sheet Totals
A2: Total | B2: =SUM(B4:B15) -> 32522.7
A4: Spirits | B4: =Spirits!K2 -> 21319.05
A5: Wine & Cava | B5: ='Wines, Cava & Champ.'!K2 -> 3704.31
A6: Plastics | B6: ='Plastic Litre or More'!K2 -> 1177.02
A7: Miniatures | B7: =Miniatures!J2 -> 115.01
A8: Small Spirit | B8: ='Spirits Less than 700ml'!K2 -> 1181.66
A9: Beers | B9: =Beers!K2 -> 1695.56
A10: Ciders | B10: =Ciders!K2 -> 1022.06
A11: Alco-pop | B11: ='Alco Pops'!K2 -> 917.97
A12: Frozen Food | C12: ='Frozen Food'!K2 -> 359.57
A13: Dried Food | B13: ='Dried Food'!K2 -> 0
A14: Soft Drinks | B14: ='Soft Drinks & Mixers'!K2 -> 1390.06
A15: Sweets | B15: ='Sweets & Crisps'!J2 -> 0

Sheet Spirits
A1: Cap. (ml) | B1: Item | C1: Buy 2025 | D1: Bar Price | E1: Shop Price | F1: Supplier | G1: Downstairs/Out back | H1: Shelves | I1: Storage Upstairs | J1: Quantity | K1: Value
K2: =SUM(K3:K470) -> 21319.05
B5: Absinthes
B9: Anis/Hierbas
A11: 700 | B11: Anis del Mono Dulce | C11: 8.79 | D11: 9.9 | E11: 9.9 | F11: Tunel | G11: 0 | H11: 2 | J11: =SUM(G11:I11) -> 2 | K11: =SUM(C11*J11) -> 17.58
A12: 700 | B12: Anis del Mono Secas | C12: 10.23 | D12: 10.9 | E12: 10.9 | F12: Tunel | H12: 3 | J12: =SUM(G12:I12) -> 3 | K12: =SUM(C12*J12) -> 30.69
A13: 700 | B13: Anis Jordi Perello Tres Caires | C13: 14.4 | D13: 16.5 | E13: 16.5 | F13: Tunel | H13: 2 | J13: =SUM(G13:I13) -> 2 | K13: =SUM(C13*J13) -> 28.8
A14: 1L | B14: Hierbas Dulce Tunel | C14: 9.85 | D14: 11.95 | E14: 11.95 | F14: Tunel | G14: 1 | H14: 7 | J14: =SUM(G14:I14) -> 8 | K14: =SUM(C14*J14) -> 78.8
A15: 1L | B15: Hierbas Mix Tunel | C15: 10.8 | D15: 12.95 | E15: 12.95 | F15: Tunel | H15: 8 | J15: =SUM(G15:I15) -> 8 | K15: =SUM(C15*J15) -> 86.4
A16: 1L | B16: Hierbas Secas Tunel | C16: 12.2 | D16: 13.95 | E16: 13.95 | F16: Tunel | H16: 7 | J16: =SUM(G16:I16) -> 7 | K16: =SUM(C16*J16) -> 85.4
A17: 700 | B17: Licor Hierbas Pazo | C17: 9.2 | D17: 10.5 | E17: 11.5 | F17: Tunel | H17: 3 | J17: =SUM(G17:I17) -> 3 | K17: =SUM(C17*J17) -> 27.6
A18: 700 | B18: Palo Tunel | C18: 9.89 | D18: 11.5 | E18: 11.95 | F18: Tunel | J18: =SUM(G18:I18) -> 0 | K18: =SUM(C18*J18) -> 0
A19: 1L | B19: Pernod | C19: 16.5 | D19: 18.5 | E19: 18.5 | F19: Tunel | H19: 4 | J19: =SUM(G19:I19) -> 4 | K19: =SUM(C19*J19) -> 66
A20: 1L | B20: Ricard | C20: 16.71 | D20: 18.5 | E20: 18.5 | F20: Tunel | H20: 4 | J20: =SUM(G20:I20) -> 4 | K20: =SUM(C20*J20) -> 66.84
B23: Aperitifs
A25: 1L | B25: Campari | C25: 17.69 | D25: 18.95 | E25: 18.95 | F25: Tunel | H25: 2 | J25: =SUM(G25:I25) -> 2 | K25: =SUM(C25*J25) -> 35.38
A26: 750 | B26: Martini Asti | C26: 8.5 | D26: 10.5 | E26: 10.5 | F26: Tunel | H26: 2 | J26: =SUM(G26:I26) -> 2 | K26: =SUM(C26*J26) -> 17
A27: 1L | B27: Martini Bianco | C27: 9.2 | D27: 10.5 | E27: 10.5 | F27: Tunel | H27: 2 | J27: =SUM(G27:I27) -> 2 | K27: =SUM(C27*J27) -> 18.4
A28: 1L | B28: Martini Dry | C28: 9.51 | D28: 10.5 | E28: 10.5 | F28: Tunel | H28: 8 | J28: =SUM(G28:I28) -> 8 | K28: =SUM(C28*J28) -> 76.08
A29: 1L | B29: Martini Rosso | C29: 9.2 | D29: 10.5 | E29: 10.5 | F29: Tunel | H29: 8 | J29: =SUM(G29:I29) -> 8 | K29: =SUM(C29*J29) -> 73.6
A30: 1L | B30: Yzaguirre Blanco | C30: 6.69 | D30: 7.5 | E30: 7.7 | F30: Tunel | H30: 3 | J30: =SUM(G30:I30) -> 3 | K30: =SUM(C30*J30) -> 20.07
B32: Brandys
A34: 1L | B34: 103 | C34: 12.34 | D34: 13.5 | E34: 13.95 | F34: Tunel | H34: 1 | J34: =SUM(G34:I34) -> 1 | K34: =SUM(C34*J34) -> 12.34
A35: 1L | B35: Asbach | C35: 17.73 | D35: 19.95 | E35: 22 | F35: Tunel | H35: 3 | J35: =SUM(G35:I35) -> 3 | K35: =SUM(C35*J35) -> 53.19
A36: 700 | B36: Cardinal Mendoza | C36: 20.23 | D36: 24 | E36: 24.95 | F36: Tunel | H36: 5 | J36: =SUM(G36:I36) -> 5 | K36: =SUM(C36*J36) -> 101.15
A37: 700 | B37: Carlos I | C37: 19.67 | D37: 23.5 | E37: 23.95 | F37: Alcodis | H37: 1 | J37: =SUM(G37:I37) -> 1 | K37: =SUM(C37*J37) -> 19.67
A38: 1L | B38: Carlos I | C38: 24.55 | D38: 29.95 | E38: 29.95 | F38: Alcodis | H38: 3 | J38: =SUM(G38:I38) -> 3 | K38: =SUM(C38*J38) -> 73.65
A39: 700 | B39: Carlos III | D39: 12.5 | E39: 12.5 | F39: Tunel | J39: =SUM(G39:I39) -> 0 | K39: =SUM(C39*J39) -> 0
A40: 700 | B40: Grand Duque De alba | C40: 21.57 | D40: 24 | E40: 24.95 | F40: Tunel | J40: =SUM(G40:I40) -> 0 | K40: =SUM(C40*J40) -> 0
A41: 700 | B41: Lepanto | C41: 19.61 | D41: 24 | E41: 24.95 | F41: Tunel | J41: =SUM(G41:I41) -> 0 | K41: =SUM(C41*J41) -> 0
A42: 1L | B42: Magno | C42: 13.04 | D42: 14.95 | E42: 14.95 | F42: Alcodis | G42: 6 | H42: 2 | J42: =SUM(G42:I42) -> 8 | K42: =SUM(C42*J42) -> 104.32
A43: 1L | B43: Metaxa 5 | C43: 14.08 | D43: 17.95 | E43: 17.95 | F43: Tunel | J43: =SUM(G43:I43) -> 0 | K43: =SUM(C43*J43) -> 0
A44: 1L | B44: Metaxa 7 | C44: 16.82 | D44: 19.95 | E44: 19.95 | F44: Tunel | H44: 2 | J44: =SUM(G44:I44) -> 2 | K44: =SUM(C44*J44) -> 33.64
A45: 700 | B45: Ponche Caballero | C45: 9.98 | D45: 11.5 | E45: 11.5 | F45: Tunel | H45: 6 | J45: =SUM(G45:I45) -> 6 | K45: =SUM(C45*J45) -> 59.88
A46: 1L | B46: Soberano | C46: 9.87 | D46: 11.5 | E46: 11.5 | F46: Tunel | G46: 3 | H46: 9 | J46: =SUM(G46:I46) -> 12 | K46: =SUM(C46*J46) -> 118.44
A47: 1L | B47: Terrys | C47: 9.92 | D47: 11.5 | E47: 11.5 | F47: Tunel | H47: 5 | J47: =SUM(G47:I47) -> 5 | K47: =SUM(C47*J47) -> 49.6
A48: 1L | B48: Tio Pedro | C48: 5.97 | D48: 7.5 | E48: 7.95 | F48: Tunel | G48: 4 | H48: 4 | J48: =SUM(G48:I48) -> 8 | K48: =SUM(C48*J48) -> 47.76
A49: 700 | B49: Torres 10 | C49: 11.77 | D49: 12.95 | E49: 12.95 | F49: Tunel | J49: =SUM(G49:I49) -> 0 | K49: =SUM(C49*J49) -> 0
A50: 700 | B50: Torres 5 | C50: 9.07 | D50: 10.95 | E50: 10.95 | F50: Tunel | J50: =SUM(G50:I50) -> 0 | K50: =SUM(C50*J50) -> 0
A51: 1L | B51: Veterano | C51: 10.74 | D51: 11.5 | E51: 11.5 | F51: Tunel | H51: 2 | J51: =SUM(G51:I51) -> 2 | K51: =SUM(C51*J51) -> 21.48
...

Sheet Wines, Cava & Champ.
A1: Cap. (ml) | B1: Item | C1: Buy 2025 | D1: Bar Price | E1: Shop Price | F1: Supplier | G1: Downstairs/Out back | H1: Shelves | I1: Storage Upstairs | J1: Quantity | K1: Value
K2: =SUM(K3:K109) -> 3704.31
B3: WINES
A4: 750 | B4: Acantus Blanco | C4: 2.64 | D4: 3.15 | E4: 3.5 | F4: Sues | G4: 83 | J4: =SUM(G4:I4) -> 83 | K4: =SUM(C4*J4) -> 219.12
A5: 750 | B5: Acantus Tinto | C5: 2.64 | D5: 3.15 | E5: 3.5 | F5: Sues | G5: 58 | J5: =SUM(G5:I5) -> 58 | K5: =SUM(C5*J5) -> 153.12
A6: 750 | B6: Acantus Rosado | C6: 2.64 | D6: 3.15 | E6: 3.5 | F6: Sues | G6: 39 | J6: =SUM(G6:I6) -> 39 | K6: =SUM(C6*J6) -> 102.96
A7: 750 | B7: Bach Tinto | C7: 3.9 | D7: 4.5 | E7: 4.9 | F7: Tunel | G7: 6 | H7: 9 | J7: =SUM(G7:I7) -> 15 | K7: =SUM(C7*J7) -> 58.5
A8: 750 | B8: Bach Seco | C8: 3.9 | D8: 4.5 | E8: 4.9 | F8: Tunel | G8: 6 | H8: 1 | J8: =SUM(G8:I8) -> 7 | K8: =SUM(C8*J8) -> 27.3
A9: 750 | B9: Bach Semi | C9: 4.22 | D9: 4.5 | E9: 4.9 | F9: Tunel | H9: 4 | J9: =SUM(G9:I9) -> 4 | K9: =SUM(C9*J9) -> 16.88
A10: 750 | B10: Bach Rosado (Blush) | C10: 3.9 | D10: 4.5 | E10: 4.9 | F10: Tunel | G10: 6 | H10: 5 | J10: =SUM(G10:I10) -> 11 | K10: =SUM(C10*J10) -> 42.9
A11: 750 | B11: Bicicletes I Peces Rosado | C11: 6.08 | D11: 6.95 | E11: 7.95 | F11: Tunel | G11: 0 | H11: 9 | J11: =SUM(G11:I11) -> 9 | K11: =SUM(C11*J11) -> 54.72
A12: 750 | B12: Bicicletes I Peces Verdejo | C12: 6.08 | D12: 6.95 | E12: 7.95 | F12: Tunel | H12: 6 | J12: =SUM(G12:I12) -> 6 | K12: =SUM(C12*J12) -> 36.48
A13: 750 | B13: Bicicletes I Peces Sauv Blanc | C13: 6.08 | D13: 6.95 | E13: 7.95 | F13: Tunel | H13: 2 | J13: =SUM(G13:I13) -> 2 | K13: =SUM(C13*J13) -> 12.16
A14: 750 | B14: Blossom Hill | C14: 5.45 | D14: 5.95 | E14: 6.5 | F14: Tunel | H14: 3 | J14: =SUM(G14:I14) -> 3 | K14: =SUM(C14*J14) -> 16.35
A15: 750 | B15: Buckfast | C15: 7.35 | D15: 8.95 | E15: 9.5 | F15: Tunel | H15: 10 | J15: =SUM(G15:I15) -> 10 | K15: =SUM(C15*J15) -> 73.5
A16: 750 | B16: Campo Viejo CRIANZA | C16: 5.43 | D16: 6.5 | E16: 6.5 | F16: GM | J16: =SUM(G16:I16) -> 0 | K16: =SUM(C16*J16) -> 0
A17: 750 | B17: Casillero Del Diablo | C17: 8.33 | D17: 9.5 | E17: 10.5 | F17: Tunel | G17: 6 | H17: 2 | J17: =SUM(G17:I17) -> 8 | K17: =SUM(C17*J17) -> 66.64
A18: 750 | B18: Conde De Caralt Rosado | C18: 2.86 | D18: 3.35 | E18: 3.75 | F18: Bonet | G18: 18 | H18: 6 | J18: =SUM(G18:I18) -> 24 | K18: =SUM(C18*J18) -> 68.64
A19: 750 | B19: Conde De Caralt Seco | C19: 2.86 | D19: 3.35 | E19: 3.75 | F19: Bonet | G19: 24 | H19: 8 | J19: =SUM(G19:I19) -> 32 | K19: =SUM(C19*J19) -> 91.52
A20: 750 | B20: Conde De Caralt Semi | C20: 2.86 | D20: 3.35 | E20: 3.75 | F20: Bonet | G20: 12 | H20: 1 | J20: =SUM(G20:I20) -> 13 | K20: =SUM(C20*J20) -> 37.18
A21: 750 | B21: Conde De Caralt Tinto | C21: 2.86 | D21: 3.35 | E21: 3.75 | F21: Bonet | G21: 24 | H21: 0 | J21: =SUM(G21:I21) -> 24 | K21: =SUM(C21*J21) -> 68.64
A22: 750 | B22: Conde de Caralt CASE 6 | C22: 16.84 | D22: 19.5 | E22: 19.5 | F22: Bonet
A23: 750 | B23: Costa D'Or Rosado | C23: 2.64 | D23: 3 | E23: 3.5 | F23: Tunel | J23: =SUM(G23:I23) -> 0 | K23: =SUM(C23*J23) -> 0
A24: 750 | B24: Costa D'Or Tinto | C24: 2.64 | D24: 3 | E24: 3.5 | F24: Tunel | H24: 4 | J24: =SUM(G24:I24) -> 4 | K24: =SUM(C24*J24) -> 10.56
A25: 750 | B25: Costa D'Or Select | C25: 2.64 | D25: 3 | E25: 3.5 | F25: Tunel | H25: 3 | J25: =SUM(G25:I25) -> 3 | K25: =SUM(C25*J25) -> 7.92
A26: 750 | B26: Echo Falls Chardonnay | C26: 5.45 | D26: 6.5 | E26: 6.95 | F26: Tunel | H26: 6 | J26: =SUM(G26:I26) -> 6 | K26: =SUM(C26*J26) -> 32.7
A27: 750 | B27: Echo Falls White Zinfandel | C27: 5.45 | D27: 6.5 | E27: 6.95 | F27: Tunel | H27: 3 | J27: =SUM(G27:I27) -> 3 | K27: =SUM(C27*J27) -> 16.35
A28: 750 | B28: Echo Falls Pinot Grigio | C28: 5.45 | D28: 6.5 | E28: 6.95 | F28: Tunel | H28: 8 | J28: =SUM(G28:I28) -> 8 | K28: =SUM(C28*J28) -> 43.6
A29: 750 | B29: Echo Falls Summer berries | C29: 5.45 | D29: 6.5 | E29: 6.95 | F29: Tunel | H29: 2 | J29: =SUM(G29:I29) -> 2 | K29: =SUM(C29*J29) -> 10.9
A30: 750 | B30: El Coto Tinto | C30: 5.23 | D30: 5.75 | E30: 5.95 | F30: Tunel | G30: 12 | H30: 4 | J30: =SUM(G30:I30) -> 16 | K30: =SUM(C30*J30) -> 83.68
A31: 750 | B31: EL Coto White | C31: 4.11 | D31: 5.25 | E31: 5.5 | F31: Tunel | G31: 6 | H31: 3 | J31: =SUM(G31:I31) -> 9 | K31: =SUM(C31*J31) -> 36.99
A32: 750 | B32: Faustino I | C32: 16.5 | D32: 18.5 | E32: 19.95 | F32: GM | H32: 3 | J32: =SUM(G32:I32) -> 3 | K32: =SUM(C32*J32) -> 49.5
A33: 750 | B33: Faustino V | C33: 8.95 | D33: 9.95 | E33: 9.95 | F33: GM | H33: 4 | J33: =SUM(G33:I33) -> 4 | K33: =SUM(C33*J33) -> 35.8
A34: 750 | B34: Faustino VII Tinto | C34: 3.57 | D34: 4.95 | E34: 4.95 | F34: GM | J34: =SUM(G34:I34) -> 0 | K34: =SUM(C34*J34) -> 0
A35: 750 | B35: I Heart Pinot Grigio | C35: 4.21 | D35: 4.95 | E35: 5.95 | F35: Bonet | G35: 6 | H35: 9 | J35: =SUM(G35:I35) -> 15 | K35: =SUM(C35*J35) -> 63.15
A36: 750 | B36: I Heart Merlot | C36: 4.21 | D36: 4.95 | E36: 5.95 | F36: Bonet | G36: 6 | H36: 5 | J36: =SUM(G36:I36) -> 11 | K36: =SUM(C36*J36) -> 46.31
A37: 750 | B37: I Heart Sauvv Blanc | C37: 4.21 | D37: 4.95 | E37: 5.95 | F37: Bonet | G37: 6 | H37: 7 | J37: =SUM(G37:I37) -> 13 | K37: =SUM(C37*J37) -> 54.73
A38: 750 | B38: I Heart Chardonnay | C38: 4.21 | D38: 4.95 | E38: 5.95 | F38: Bonet | H38: 12 | J38: =SUM(G38:I38) -> 12 | K38: =SUM(C38*J38) -> 50.52
A39: 750 | B39: I Heart Rosado | C39: 4.21 | D39: 4.95 | E39: 5.95 | F39: Bonet | H39: 6 | J39: =SUM(G39:I39) -> 6 | K39: =SUM(C39*J39) -> 25.26
A40: 750 | B40: JamShed Chardonnay | C40: 6.2 | D40: 7.5 | E40: 7.5 | F40: Tunel | H40: 3 | J40: =SUM(G40:I40) -> 3 | K40: =SUM(C40*J40) -> 18.6
...

Sheet Spirits Less than 700ml
A1: Cap. (ml) | B1: 44 | C1: Buy 2025 | D1: Bar Price | E1: Shop Price | F1: Supplier | G1: Downstairs/Out back | H1: Shelves | I1: Storage Upstairs | J1: Quantity | K1: Value
K2: =SUM(K3:K107) -> 1181.66
B4: Plastic 500ml
A7: 500 | B7: After Red | C7: 0 | E7: 5.95 | F7: Don Mallorca | H7: 5 | J7: =SUM(G7:I7) -> 5 | K7: =SUM(C7*J7) -> 0
A8: 500 | B8: Frans Strawberry | C8: 0 | E8: 5.95 | F8: Don Mallorca | H8: 4
B11: Plastic 350ml
B13: Absenta Various | E13: 7.5 | F13: Tunel | J13: =SUM(G13:I13) -> 0 | K13: =SUM(C13*J13) -> 0
A14: 350 | B14: Nadaluxe | E14: 3.95 | F14: Tunel | J14: =SUM(G14:I14) -> 0 | K14: =SUM(C14*J14) -> 0
B15: Palmbridge | C15: 4.22 | E15: 4.95 | F15: Tunel | H15: 2 | J15: =SUM(G15:I15) -> 2 | K15: =SUM(C15*J15) -> 8.44
B16: Palmbridge Pink | C16: 4.71 | E16: 5.5 | F16: Tunel | J16: =SUM(G16:I16) -> 0 | K16: =SUM(C16*J16) -> 0
B17: Peach Schnapps | C17: 3.36 | E17: 4.95 | F17: Tunel | H17: 10 | J17: =SUM(G17:I17) -> 10 | K17: =SUM(C17*J17) -> 33.6
A18: 350 | B18: Ron Tobacco | C18: 4.48 | E18: 4.95 | F18: Tunel | H18: 4 | J18: =SUM(G18:I18) -> 4 | K18: =SUM(C18*J18) -> 17.92
A19: 350 | B19: Rushkinoff | C19: 4.36 | E19: 4.95 | F19: Tunel | H19: 13 | J19: =SUM(G19:I19) -> 13 | K19: =SUM(C19*J19) -> 56.68
A20: 350 | B20: Rushkinoff Caramel | C20: 3.9 | E20: 4.95 | F20: Tunel | H20: 9 | J20: =SUM(G20:I20) -> 9 | K20: =SUM(C20*J20) -> 35.1
A21: 350 | B21: Sambuca White | C21: 5.02 | E21: 5.95 | F21: Tunel | H21: 1 | J21: =SUM(G21:I21) -> 1 | K21: =SUM(C21*J21) -> 5.02
B22: Strawberry Schnapps | C22: 3.36 | E22: 3.95 | F22: Tunel | H22: 8 | J22: =SUM(G22:I22) -> 8 | K22: =SUM(C22*J22) -> 26.88
A23: 350 | B23: Tia Nadal | C23: 3.54 | E23: 3.95 | F23: Tunel | G23: 2 | J23: =SUM(G23:I23) -> 2 | K23: =SUM(C23*J23) -> 7.08
A24: 350 | B24: Zibao Mojito | C24: 3.67 | E24: 3.95 | F24: Tunel | H24: 1 | J24: =SUM(G24:I24) -> 1 | K24: =SUM(C24*J24) -> 3.67
A25: 350 | B25: Zibao Pina Colada | C25: 3.76 | E25: 3.95 | F25: Tunel | H25: 9 | J25: =SUM(G25:I25) -> 9 | K25: =SUM(C25*J25) -> 33.84
B27: Glass 350ml
A29: 350 | B29: Buckfast | C29: 4.42 | E29: 5.5 | F29: Tunel | H29: 19 | J29: =SUM(G29:I29) -> 19 | K29: =SUM(C29*J29) -> 83.98
A30: 350 | B30: Smirnoff | C30: 6.22 | E30: 7.5 | F30: Guy in Van | G30: 13 | H30: 6 | J30: =SUM(G30:I30) -> 19 | K30: =SUM(C30*J30) -> 118.18
A31: 350 | B31: Southern Comfort | C31: 8.68 | E31: 9.95 | F31: Tunel | H31: 1 | J31: =SUM(G31:I31) -> 1 | K31: =SUM(C31*J31) -> 8.68
B33: Glass
A36: 200 | B36: Absinthe Bewitched 89.9% | C36: 6 | E36: 7.95 | F36: Don Mallorca | H36: 25 | J36: =SUM(G36:I36) -> 25 | K36: =SUM(C36*J36) -> 150
A37: 200 | B37: Angustura Bitter | C37: 10.43 | D37: 11.9 | E37: 11.9 | F37: Tunel | H37: 4 | J37: =SUM(G37:I37) -> 4 | K37: =SUM(C37*J37) -> 41.72
A38: 200 | B38: Bacardi | C38: 5.4 | E38: 5.95 | F38: Tunel | H38: 8 | J38: =SUM(G38:I38) -> 8 | K38: =SUM(C38*J38) -> 43.2
B39: Bells | C39: 3.81 | E39: 4.95 | F39: Tunel | J39: =SUM(G39:I39) -> 0 | K39: =SUM(C39*J39) -> 0
A40: 200 | B40: Captain Morgan | C40: 5.09 | E40: 5.95 | F40: Tunel | J40: =SUM(G40:I40) -> 0 | K40: =SUM(C40*J40) -> 0
B41: Famous Grouse | C41: 4.5 | F41: Guy in Van | G41: 12 | H41: 17 | J41: =SUM(G41:I41) -> 29 | K41: =SUM(C41*J41) -> 130.5
B42: Gordons Gin | C42: 5.09 | E42: 5.95 | F42: Tunel | H42: 4 | J42: =SUM(G42:I42) -> 4 | K42: =SUM(C42*J42) -> 20.36
B43: Grey Goose | E43: 11.9 | F43: Tunel | J43: =SUM(G43:I43) -> 0 | K43: =SUM(C43*J43) -> 0
B44: Hierbas Dulces | C44: 3.94 | E44: 4.5 | F44: Tunel | H44: 10 | J44: =SUM(G44:I44) -> 10 | K44: =SUM(C44*J44) -> 39.4
B45: Hierbas Mix | C45: 4.49 | E45: 5.5 | F45: Tunel | H45: 11 | J45: =SUM(G45:I45) -> 11 | K45: =SUM(C45*J45) -> 49.39
B46: Hierbas Secas | C46: 5.08 | E46: 6.5 | F46: Tunel | H46: 5 | J46: =SUM(G46:I46) -> 5 | K46: =SUM(C46*J46) -> 25.4
B47: J&B | E47: 4.95 | F47: Tunel | J47: =SUM(G47:I47) -> 0 | K47: =SUM(C47*J47) -> 0
A48: 350 | B48: Jack daniels | C48: 13.32 | E48: 14.95 | F48: Tunel | H48: 3 | J48: =SUM(G48:I48) -> 3 | K48: =SUM(C48*J48) -> 39.96
B49: Jager | C49: 4.77 | E49: 5.95 | F49: Tunel | H49: 8 | J49: =SUM(G49:I49) -> 8 | K49: =SUM(C49*J49) -> 38.16
B50: Smirnoff | C50: 3.5 | E50: 4.5 | F50: Guy in Van | G50: 41 | H50: 6 | J50: =SUM(G50:I50) -> 47 | K50: =SUM(C50*J50) -> 164.5

Sheet Plastic Litre or More
A1: Cap. (ml) | B1: Item | C1: Buy Price 2025 | D1: Bar Price | E1: Shop Price | F1: Supplier | G1: Downstairs/Out back | H1: Shelves | I1: Storage Upstairs | J1: Quantity | K1: Value
K2: =SUM(K3:K95) -> 1177.02
B3: Plastic Litres
A5: 1L | B5: 103 | C5: 12.39 | E5: 13.95 | F5: Tunel | H5: 0 | J5: =SUM(G5:I5) -> 0 | K5: =SUM(C5*J5) -> 0
A6: 1L | B6: After Blue | C6: 10.76 | D6: 13.95 | E6: 14.95 | F6: Don Mallorca | G6: 6 | H6: 2 | J6: =SUM(G6:I6) -> 8 | K6: =SUM(C6*J6) -> 86.08
B7: After Red | C7: 10.76 | D7: 13.95 | E7: 14.95 | F7: Don Mallorca | G7: 6 | H7: 6 | J7: =SUM(G7:I7) -> 12 | K7: =SUM(C7*J7) -> 129.12
A8: 1L | B8: Cherry Brandy | C8: 6.71 | D8: 7.95 | E8: 7.95 | F8: Tunel | H8: 4 | J8: =SUM(G8:I8) -> 4 | K8: =SUM(C8*J8) -> 26.84
A9: 1L | B9: Famous Grouse | C9: 14.43 | E9: 16.95 | F9: Tunel | H9: 2 | J9: =SUM(G9:I9) -> 2 | K9: =SUM(C9*J9) -> 28.86
A10: 1L | B10: Gordons | C10: 14.47 | E10: 15.95 | F10: Tunel | J10: =SUM(G10:I10) -> 0 | K10: =SUM(C10*J10) -> 0
A11: 1L | B11: Jerikoff Blue | C11: 8.5 | E11: 8.95 | F11: Don Mallorca | G11: 5 | H11: 3 | J11: =SUM(G11:I11) -> 8 | K11: =SUM(C11*J11) -> 68
A12: 1L | B12: Jet Boom Red | C12: 12.7 | E12: 14.95 | F12: Tunel | J12: =SUM(G12:I12) -> 0 | K12: =SUM(C12*J12) -> 0
A13: 1L | B13: Larios | C13: 12.45 | E13: 13.95 | F13: Tunel | H13: 3 | J13: =SUM(G13:I13) -> 3 | K13: =SUM(C13*J13) -> 37.35
A14: 1L | B14: Nadaluxe | C14: 7.07 | E14: 8.95 | F14: Tunel | H14: 6 | J14: =SUM(G14:I14) -> 6 | K14: =SUM(C14*J14) -> 42.42
A15: 1L | B15: Palmbridge | C15: 7.67 | E15: 9.95 | F15: Tunel | J15: =SUM(G15:I15) -> 0 | K15: =SUM(C15*J15) -> 0
A16: 1L | B16: Palmbridge Pink | C16: 9.35 | E16: 10.95 | F16: Tunel | G16: 9 | H16: 5 | J16: =SUM(G16:I16) -> 14 | K16: =SUM(C16*J16) -> 130.9
A17: 1L | B17: Peach Schnapps | C17: 5.13 | E17: 6.95 | F17: Tunel | G17: 1 | H17: 5 | J17: =SUM(G17:I17) -> 6 | K17: =SUM(C17*J17) -> 30.78
A18: 1L | B18: Ron Miel Tobacco | C18: 7.03 | E18: 8.5 | F18: Tunel | H18: 11 | J18: =SUM(G18:I18) -> 11 | K18: =SUM(C18*J18) -> 77.33
A19: 1L | B19: Rushkinoff | C19: 7.67 | E19: 9.95 | F19: Tunel | H19: 12 | J19: =SUM(G19:I19) -> 12 | K19: =SUM(C19*J19) -> 92.04
B20: Rushkinoff Caramel | C20: 7.75 | E20: 9.95 | F20: Tunel | H20: 9 | J20: =SUM(G20:I20) -> 9 | K20: =SUM(C20*J20) -> 69.75
A21: 1L | B21: Sambuca | C21: 10.35 | E21: 12.95 | F21: Tunel | H21: 3 | J21: =SUM(G21:I21) -> 3 | K21: =SUM(C21*J21) -> 31.05
A22: 1L | B22: Soberano | C22: 9.77 | E22: 11.5 | F22: Tunel | H22: 9 | J22: =SUM(G22:I22) -> 9 | K22: =SUM(C22*J22) -> 87.93
A23: 1L | B23: Tia Nadal | C23: 7.21 | E23: 8.95 | F23: Tunel | H23: 7 | J23: =SUM(G23:I23) -> 7 | K23: =SUM(C23*J23) -> 50.47
A24: 1L | B24: Tobacco | C24: 7.67 | E24: 9.95 | F24: Tunel | J24: =SUM(G24:I24) -> 0 | K24: =SUM(C24*J24) -> 0
A25: 1L | B25: Triple Sec | C25: 7.53 | E25: 9.95 | F25: Tunel | H25: 4 | J25: =SUM(G25:I25) -> 4 | K25: =SUM(C25*J25) -> 30.12
A26: 1L | B26: Tunel Cinnamon Boom | C26: 11.95 | D26: 12.95 | E26: 13.95 | F26: Tunel | H26: 1 | J26: =SUM(G26:I26) -> 1 | K26: =SUM(C26*J26) -> 11.95
B30: 3L Plastics
B33: Hierbas Secas 3L | C33: 24.96 | D33: 27.5 | E33: 27.9 | F33: Tunel | G33: 4 | H33: 1 | J33: =SUM(G33:I33) -> 5 | K33: =SUM(C33*J33) -> 124.8
B34: Hierbas Mix 3L | C34: 23.51 | D34: 25.9 | E34: 25.9 | F34: Tunel | H34: 0 | J34: =SUM(G34:I34) -> 0 | K34: =SUM(C34*J34) -> 0
B35: Hierbas Dulce 3L | C35: 21.23 | D35: 23.9 | E35: 24.9 | F35: Tunel | H35: 1 | J35: =SUM(G35:I35) -> 1 | K35: =SUM(C35*J35) -> 21.23
B36: Banana Liquer 3L | C36: 17.47 | D36: 19.5 | E36: 20 | F36: Tunel | J36: =SUM(G36:I36) -> 0 | K36: =SUM(C36*J36) -> 0
B37: Triple Sec 3L | C37: 19.78 | D37: 22 | E37: 23 | F37: Tunel | J37: =SUM(G37:I37) -> 0 | K37: =SUM(C37*J37) -> 0
B38: Limoncello Ferrone 3L | C38: 17.78 | D38: 18.95 | E38: 18.9 | F38: Tunel | J38: =SUM(G38:I38) -> 0 | K38: =SUM(C38*J38) -> 0
B39: Caiman Love 3L Plastic | C39: 15.06 | D39: 16.95 | E39: 19.5 | F39: Tunel | J39: =SUM(G39:I39) -> 0 | K39: =SUM(C39*J39) -> 0

Sheet Miniatures
A1: Cap. (ml) | B1: Item | C1: Buy 2025 | D1: Bar Price | E1: Shop Price | F1: Downstairs/Out back | G1: Shelves | H1: Storage Upstairs | I1: Quantity | J1: Value
J2: =SUM(J3:J105) -> 115.01
B4: Single Bottles
A6: 40 | B6: Absenta | C6: 1.27 | D6: 2.5 | E6: 2.5 | G6: 19 | I6: =SUM(F6:H6) -> 19 | J6: =SUM(C6*I6) -> 24.13
A7: 50 | B7: Absolut Blue | C7: 1.44 | D7: 2.5 | E7: 2.5 | I7: =SUM(F7:H7) -> 0 | J7: =SUM(C7*I7) -> 0
A8: 50 | B8: Absolut Mandarin | C8: 1.52 | D8: 2.5 | E8: 2.5 | I8: =SUM(F8:H8) -> 0 | J8: =SUM(C8*I8) -> 0
A9: 50 | B9: Absolut Peach | C9: 1.44 | D9: 2.5 | E9: 2.5 | I9: =SUM(F9:H9) -> 0 | J9: =SUM(C9*I9) -> 0
A10: 50 | B10: Absolut Pear | C10: 1.44 | D10: 2.5 | E10: 2.5 | I10: =SUM(F10:H10) -> 0 | J10: =SUM(C10*I10) -> 0
A11: 50 | B11: Absolut Raspberry | C11: 1.52 | D11: 2.5 | E11: 2.5 | G11: 12 | I11: =SUM(F11:H11) -> 12 | J11: =SUM(C11*I11) -> 18.24
A12: 50 | B12: Absolut Vanilla | C12: 1.44 | D12: 2.5 | E12: 2.5 | G12: 7 | I12: =SUM(F12:H12) -> 7 | J12: =SUM(C12*I12) -> 10.08
A13: 40 | B13: Asbach | D13: 2.5 | E13: 2.5 | I13: =SUM(F13:H13) -> 0 | J13: =SUM(C13*I13) -> 0
A14: 50 | B14: Bacardi | D14: 2 | E14: 2 | G14: 15 | I14: =SUM(F14:H14) -> 15 | J14: =SUM(C14*I14) -> 0
A15: 50 | B15: Bombay Sapphire | D15: 2.5 | E15: 2.5 | G15: 6 | I15: =SUM(F15:H15) -> 6 | J15: =SUM(C15*I15) -> 0
A16: 50 | B16: Brugal | D16: 2.5 | E16: 2.5 | G16: 1 | I16: =SUM(F16:H16) -> 1 | J16: =SUM(C16*I16) -> 0
A17: 50 | B17: Courvoisier | C17: 2.55 | D17: 4 | E17: 4 | I17: =SUM(F17:H17) -> 0 | J17: =SUM(C17*I17) -> 0
A18: 50 | B18: Famous Grouse | D18: 2 | E18: 2 | G18: 6 | I18: =SUM(F18:H18) -> 6 | J18: =SUM(C18*I18) -> 0
A19: 50 | B19: Gordons | C19: 1.22 | D19: 2.5 | E19: 2.5 | G19: 4 | I19: =SUM(F19:H19) -> 4 | J19: =SUM(C19*I19) -> 4.88
A20: 50 | B20: Jack Daniels | D20: 2.5 | E20: 2.5 | I20: =SUM(F20:H20) -> 0 | J20: =SUM(C20*I20) -> 0
A21: 40 | B21: Jagermeister | C21: 1.34 | D21: 2.5 | E21: 2.5 | G21: 2 | I21: =SUM(F21:H21) -> 2 | J21: =SUM(C21*I21) -> 2.68
A22: 50 | B22: Jameson | C22: 1.41 | D22: 2.5 | E22: 2.5 | G22: 1 | I22: =SUM(F22:H22) -> 1 | J22: =SUM(C22*I22) -> 1.41
A23: 50 | B23: Johnnie Walker Black Label | C23: 2.01 | D23: 3 | E23: 3 | I23: =SUM(F23:H23) -> 0 | J23: =SUM(C23*I23) -> 0
A24: 50 | B24: Johnnie Walker Red Label | C24: 1.45 | D24: 2.5 | E24: 2.5 | G24: 5 | I24: =SUM(F24:H24) -> 5 | J24: =SUM(C24*I24) -> 7.25
A25: 40 | B25: Kraken | G25: 30 | I25: =SUM(F25:H25) -> 30 | J25: =SUM(C25*I25) -> 0
A26: 50 | B26: Larios | G26: 7 | I26: =SUM(F26:H26) -> 7 | J26: =SUM(C26*I26) -> 0
A27: 50 | B27: Larios Rose | C27: 1.45 | D27: 2.5 | E27: 2.5 | I27: =SUM(F27:H27) -> 0 | J27: =SUM(C27*I27) -> 0
A28: 40 | B28: Malibu | G28: 5 | I28: =SUM(F28:H28) -> 5 | J28: =SUM(C28*I28) -> 0
A29: 50 | B29: Russian Standard | C29: 1.24 | D29: 2.5 | E29: 2.5 | I29: =SUM(F29:H29) -> 0 | J29: =SUM(C29*I29) -> 0
A30: 50 | B30: Smirnoff | D30: 2 | E30: 2 | G30: 10 | I30: =SUM(F30:H30) -> 10 | J30: =SUM(C30*I30) -> 0
A31: 50 | B31: Southern Comfort | D31: 2.5 | E31: 2.5 | G31: 4 | I31: =SUM(F31:H31) -> 4 | J31: =SUM(C31*I31) -> 0
A32: 20 | B32: Underberg | D32: 1.5 | E32: 1.5 | G32: 12 | I32: =SUM(F32:H32) -> 12 | J32: =SUM(C32*I32) -> 0
A33: 20 | B33: Underberg 3 pk | D33: 4 | E33: 4 | G33: 10 | I33: =SUM(F33:H33) -> 10 | J33: =SUM(C33*I33) -> 0
B36: Packs
A38: 40 | B38: Bag 10 | C38: 8.89 | D38: 12 | E38: 12 | I38: =SUM(F38:H38) -> 0 | J38: =SUM(C38*I38) -> 0
A39: 40 | B39: Bag 7 | C39: 7.31 | D39: 10 | E39: 10 | I39: =SUM(F39:H39) -> 0 | J39: =SUM(C39*I39) -> 0
A40: 40 | B40: Bag 5 | C40: 5.49 | D40: 7.5 | E40: 7.5 | G40: 1 | I40: =SUM(F40:H40) -> 1 | J40: =SUM(C40*I40) -> 5.49
I41: =SUM(F41:H41) -> 0 | J41: =SUM(C41*I41) -> 0
B42: 3 Pack Hierbas | C42: 4.39 | E42: 5.95 | G42: 3 | I42: =SUM(F42:H42) -> 3 | J42: =SUM(C42*I42) -> 13.17
B43: 6 Pack Blue | C43: 5.85 | E43: 7.95 | I43: =SUM(F43:H43) -> 0 | J43: =SUM(C43*I43) -> 0
B44: 5 Pack Barman | C44: 4.65 | E44: 5.95 | G44: 5 | I44: =SUM(F44:H44) -> 5 | J44: =SUM(C44*I44) -> 23.25
B45: 6 Pack Miniatures | C45: 4.43 | E45: 6.5 | G45: 1 | I45: =SUM(F45:H45) -> 1 | J45: =SUM(C45*I45) -> 4.43
...

Sheet Beers
A1: Cap. (ml) | B1: Item | C1: Buy 2025 | D1: Bar Price | E1: Shop Price | F1: Supplier | G1: Downstairs/Out back | H1: Shelves | I1: Storage Upstairs | J1: Quantity | K1: Value
K2: =SUM(K3:K102) -> 1695.56
B3: Beers
A6: 330 | B6: Birra Moretti Bottle 330ml | C6: 1.11 | D6: 1.4 | E6: 1.5 | F6: TransMallorca | H6: 5 | J6: =SUM(G6:I6) -> 5 | K6: =SUM(C6*J6) -> 5.55
A7: 330 | B7: Birra Moretti Bottle Case 24x330ml | C7: 26.62 | D7: 30 | E7: 33 | F7: TransMallorca | I7: 1 | J7: =SUM(G7:I7) -> 1 | K7: =SUM(C7*J7) -> 26.62
A9: 330 | B9: Budweiser Bottle Case 24x330ml | C9: 21.47 | D9: 26 | E9: 26 | F9: Voldis / Tunel / HG | I9: 3 | J9: =SUM(G9:I9) -> 3 | K9: =SUM(C9*J9) -> 64.41
A10: 330 | B10: Budweiser Bottle 330ml | C10: 0.89 | D10: 1.4 | E10: 1.5 | F10: Voldis / Tunel / HG | J10: =SUM(G10:I10) -> 0 | K10: =SUM(C10*J10) -> 0
A11: 330 | B11: Budweiser Can 330ml | C11: 0.65 | D11: 0.85 | E11: 0.95 | F11: Voldis | J11: =SUM(G11:I11) -> 0 | K11: =SUM(C11*J11) -> 0
A12: 330 | B12: Budweiser Can Case 24x330ml | C12: 16.02 | D12: 20 | E12: 20 | F12: Voldis | I12: 5 | J12: =SUM(G12:I12) -> 5 | K12: =SUM(C12*J12) -> 80.1
A14: 500 | B14: Carling Can 500ml | C14: 30.2 | D14: 33 | E14: 35 | F14: Tindale | J14: =SUM(G14:I14) -> 0 | K14: =SUM(C14*J14) -> 0
A15: 500 | B15: Carling Can Case 24x500ml | C15: 1.26 | D15: 1.5 | E15: 1.6 | F15: Tindale | J15: =SUM(G15:I15) -> 0 | K15: =SUM(C15*J15) -> 0
A17: 330 | B17: Carlsberg Bottle 330ml | D17: 1.5 | E17: 1.5 | F17: Comabe | J17: =SUM(G17:I17) -> 0 | K17: =SUM(C17*J17) -> 0
A18: 330 | B18: Carlsberg Bottle Case 24x330ml | C18: 24.91 | D18: 27 | E18: 30 | F18: Comabe | I18: 1 | J18: =SUM(G18:I18) -> 1 | K18: =SUM(C18*J18) -> 24.91
A21: 330 | B21: Coors Light Bottle Case 24x33cl | C21: 22.63 | D21: 26 | E21: 28 | F21: Tunel / Comabe | I21: 7 | J21: =SUM(G21:I21) -> 7 | K21: =SUM(C21*J21) -> 158.41
A22: 330 | B22: Coors Light Bottle 33cl | C22: 0.83 | D22: 1.25 | E22: 1.5 | F22: Tunel / Comabe | J22: =SUM(G22:I22) -> 0 | K22: =SUM(C22*J22) -> 0
A23: 330 | B23: Coors Light Bottle 6x33cl | E23: 7.95 | F23: Tunel / Comabe | J23: =SUM(G23:I23) -> 0 | K23: =SUM(C23*J23) -> 0
A24: 500 | B24: Coors Light Can 500ml | C24: 1.59 | D24: 1.8 | E24: 1.95 | F24: Voldis / Tindale | J24: =SUM(G24:I24) -> 0 | K24: =SUM(C24*J24) -> 0
A25: 500 | B25: Coors Light Can 24x500ml | C25: 38.33 | D25: 42 | E25: 44 | F25: Voldis / Tindale | J25: =SUM(G25:I25) -> 0 | K25: =SUM(C25*J25) -> 0
A27: 350 | B27: Corona Bottle Case 24x35cl | C27: 21.28 | D27: 27 | E27: 30 | F27: Voldis / Tunel / HG | I27: 5 | J27: =SUM(G27:I27) -> 5 | K27: =SUM(C27*J27) -> 106.4
A28: 350 | B28: Corona Bottle 35cl | C28: 0.88 | D28: 1.4 | E28: 1.5 | F28: Voldis / Tunel / HG | J28: =SUM(G28:I28) -> 0 | K28: =SUM(C28*J28) -> 0
A29: 350 | B29: Corona Bottle 6x35cl | C29: 5.31 | D29: 7.5 | E29: 7.95 | F29: Voldis / Tunel / HG | J29: =SUM(G29:I29) -> 0 | K29: =SUM(C29*J29) -> 0
A30: 330 | B30: Corona LATA 33cl | C30: 0.7 | D30: 0.85 | E30: 0.95 | F30: Voldis | J30: =SUM(G30:I30) -> 0 | K30: =SUM(C30*J30) -> 0
A31: 330 | B31: Corona LATA 6x33cl | C31: 4.2 | D31: 5.5 | E31: 5.5 | F31: Voldis | J31: =SUM(G31:I31) -> 0 | K31: =SUM(C31*J31) -> 0
A32: 330 | B32: Corona LATA 24x33cl | C32: 15.53 | D32: 20 | E32: 20 | F32: Voldis | J32: =SUM(G32:I32) -> 0 | K32: =SUM(C32*J32) -> 0
A34: 330 | B34: Cruzcampo Can 33cl | C34: 0.42 | D34: 0.65 | E34: 0.7 | F34: TransMallorca | J34: =SUM(G34:I34) -> 0 | K34: =SUM(C34*J34) -> 0
A35: 330 | B35: Cruzcampo Can Case 24x33cl | C35: 12.35 | D35: 14 | E35: 16 | F35: TransMallorca | I35: 3 | J35: =SUM(G35:I35) -> 3 | K35: =SUM(C35*J35) -> 37.05
A36: 330 | B36: Cruzcampo Shandy Can 33cl | C36: 0.5 | D36: 0.75 | E36: 0.75 | F36: TransMallorca | J36: =SUM(G36:I36) -> 0 | K36: =SUM(C36*J36) -> 0
A37: 330 | B37: Cruzcampo Shandy Can Case 24x33cl | C37: 11.9 | D37: 13 | E37: 13 | F37: TransMallorca | I37: 2 | J37: =SUM(G37:I37) -> 2 | K37: =SUM(C37*J37) -> 23.8
A39: 330 | B39: Desperados Bottle Case 24x33cl | C39: 23 | D39: 29 | E39: 30 | F39: TransMallorca | I39: 2 | J39: =SUM(G39:I39) -> 2 | K39: =SUM(C39*J39) -> 46
A40: 330 | B40: Desprados Bottle 33cl | C40: 0.96 | D40: 1.4 | E40: 1.5 | F40: TransMallorca | J40: =SUM(G40:I40) -> 0 | K40: =SUM(C40*J40) -> 0
A41: 330 | B41: Desprados Bottle 6 x33cl | C41: 5.75 | D41: 7.5 | E41: 7.95 | F41: TransMallorca | J41: =SUM(G41:I41) -> 0 | K41: =SUM(C41*J41) -> 0
A42: 500 | B42: Desperados Can 500ml | C42: 1.24 | D42: 1.5 | E42: 1.6 | F42: TransMallorca | J42: =SUM(G42:I42) -> 0 | K42: =SUM(C42*J42) -> 0
A43: 500 | B43: Desperados Can Case 24x500ml | C43: 29.85 | D43: 34 | E43: 36 | F43: TransMallorca | I43: 2 | J43: =SUM(G43:I43) -> 2 | K43: =SUM(C43*J43) -> 59.7
A46: 500 | B46: Erdinger 500ml Bottle | C46: 1.73 | D46: 1.95 | E46: 2 | F46: Tunel | J46: =SUM(G46:I46) -> 0 | K46: =SUM(C46*J46) -> 0
A47: 500 | B47: Erdinger Case 12 x 500ml Bottle | C47: 20.81 | D47: 22.5 | E47: 24 | F47: Tunel | J47: =SUM(G47:I47) -> 0 | K47: =SUM(C47*J47) -> 0
A50: 330 | B50: Estrella Damm Can 330ml | C50: 0.73 | D50: 0.9 | E50: 0.9 | F50: Comabe | J50: =SUM(G50:I50) -> 0 | K50: =SUM(C50*J50) -> 0
A51: 330 | B51: Estrella Damm Can Case 24x330ml | C51: 17.32 | D51: 18.5 | E51: 20 | F51: Comabe | I51: 0 | J51: =SUM(G51:I51) -> 0 | K51: =SUM(C51*J51) -> 0
A52: 500 | B52: Estrella Damm Can 500ml | C52: 1.12 | D52: 1.3 | E52: 1.4 | F52: Comabe | J52: =SUM(G52:I52) -> 0 | K52: =SUM(C52*J52) -> 0
A53: 500 | B53: Estrella Damm Can Case 24x500ml | C53: 27 | D53: 30 | E53: 32 | F53: Comabe | I53: 3 | J53: =SUM(G53:I53) -> 3 | K53: =SUM(C53*J53) -> 81
A54: 330 | B54: Estrella Damm Bottle 330ml | C54: 1.04 | D54: 1.4 | E54: 1.5 | F54: Comabe | J54: =SUM(G54:I54) -> 0 | K54: =SUM(C54*J54) -> 0
...

Sheet Ciders
A1: Cap. (ml) | B1: Item | C1: Buy 2025 | D1: Bar Price | E1: Shop Price | F1: Supplier | G1: Downstairs/Out back | H1: Shelves | I1: Storage Upstairs | J1: Quantity | K1: Value
K2: =SUM(K3:K103) -> 1022.06
B3: CIDERS
A6: 500 | B6: Koppaberg Can Pear | C6: 1.65 | D6: 1.95 | E6: 2.25 | F6: Tunel | J6: =SUM(G6:I6) -> 0 | K6: =SUM(C6*J6) -> 0
A7: 500 | B7: Koppaberg Can Pear Case 24 | C7: 39.56 | D7: 44.5 | E7: 46 | F7: Tunel | J7: =SUM(G7:I7) -> 0 | K7: =SUM(C7*J7) -> 0
A8: 500 | B8: Koppaberg Can Strawberry Lime | C8: 1.65 | D8: 1.95 | E8: 2.25 | F8: Tunel | J8: =SUM(G8:I8) -> 0 | K8: =SUM(C8*J8) -> 0
A9: 500 | B9: Koppaberg Can Strawberry Lime Case 24 | C9: 39.56 | D9: 44.5 | E9: 46 | F9: Tunel | I9: 7 | J9: =SUM(G9:I9) -> 7 | K9: =SUM(C9*J9) -> 276.92
A10: 500 | B10: Koppaberg Can Mix Fruit Tropical | C10: 1.65 | D10: 1.95 | E10: 2.25 | F10: Tunel | J10: =SUM(G10:I10) -> 0 | K10: =SUM(C10*J10) -> 0
A11: 500 | B11: Koppaberg Can Mix Fruit Tropical | C11: 39.56 | D11: 44.5 | E11: 46 | F11: Tunel | J11: =SUM(G11:I11) -> 0 | K11: =SUM(C11*J11) -> 0
A12: 500 | B12: Koppaberg Can Mix Fruit | C12: 1.65 | D12: 1.95 | E12: 2.25 | F12: Tunel | J12: =SUM(G12:I12) -> 0 | K12: =SUM(C12*J12) -> 0
A13: 500 | B13: Koppaberg Can Mix Fruit Case 24 | C13: 39.56 | D13: 44.5 | E13: 46 | F13: Tunel | I13: 6 | J13: =SUM(G13:I13) -> 6 | K13: =SUM(C13*J13) -> 237.36
A14: 330 | B14: Koppaberg Can Strawberry Lime 0% Alc | C14: 1.38 | D14: 1.7 | E14: 1.85 | F14: Tunel | J14: =SUM(G14:I14) -> 0 | K14: =SUM(C14*J14) -> 0
A15: 330 | B15: Koppaberg Can Strawberry Lime Pack 12 0% Alc | C15: 16.56 | D15: 18.75 | E15: 20 | F15: Tunel | J15: =SUM(G15:I15) -> 0 | K15: =SUM(C15*J15) -> 0
A18: 330 | B18: Magners Bottle 33cl | C18: 1.41 | D18: 1.75 | E18: 1.75 | F18: Tunel / Comabe | J18: =SUM(G18:I18) -> 0 | K18: =SUM(C18*J18) -> 0
A19: 330 | B19: Magners Bottle Case 33clx24 | C19: 33.8 | D19: 37.5 | E19: 39 | F19: Tunel / Comabe | I19: 5 | J19: =SUM(G19:I19) -> 5 | K19: =SUM(C19*J19) -> 169
A20: 568 | B20: Magners Bottle 568ml | C20: 1.96 | D20: 2.5 | E20: 2.5 | F20: Tunel / Comabe | J20: =SUM(G20:I20) -> 0 | K20: =SUM(C20*J20) -> 0
A21: 568 | B21: Magners Bottle Case 568mlx12 | C21: 23.52 | D21: 27 | E21: 30 | F21: Tunel / Comabe | I21: 6 | J21: =SUM(G21:I21) -> 6 | K21: =SUM(C21*J21) -> 141.12
A22: 500 | B22: Magners Can 500ml | C22: 1.401 | D22: 1.9 | E22: 1.95 | F22: Tunel / Comabe | J22: =SUM(G22:I22) -> 0 | K22: =SUM(C22*J22) -> 0
A23: 500 | B23: Magners Can Case 500mlx24 | C23: 33.63 | D23: 38 | E23: 42 | F23: Tunel / Comabe | I23: 1 | J23: =SUM(G23:I23) -> 1 | K23: =SUM(C23*J23) -> 33.63
J24: =SUM(G24:I24) -> 0 | K24: =SUM(C24*J24) -> 0
A25: 330 | B25: Orchard thieves 330ml Can | C25: 1.13 | D25: 1.4 | E25: 1.6 | F25: GM | J25: =SUM(G25:I25) -> 0 | K25: =SUM(C25*J25) -> 0
A26: 330 | B26: Orchard thieves 24x330ml Can | C26: 27.12 | D26: 30 | E26: 33 | F26: GM | J26: =SUM(G26:I26) -> 0 | K26: =SUM(C26*J26) -> 0
J27: =SUM(G27:I27) -> 0 | K27: =SUM(C27*J27) -> 0
J28: =SUM(G28:I28) -> 0 | K28: =SUM(C28*J28) -> 0
A29: 500 | B29: Rekordelig Can Passion Fruit | C29: 1.4 | D29: 1.7 | E29: 1.9 | F29: Voldis / Comabe | J29: =SUM(G29:I29) -> 0 | K29: =SUM(C29*J29) -> 0
A30: 500 | B30: Rekordelig Can Passion Fruit Case 24 | C30: 33.51 | D30: 38 | E30: 40 | F30: Voldis / Comabe | J30: =SUM(G30:I30) -> 0 | K30: =SUM(C30*J30) -> 0
A31: 500 | B31: Rekordelig Can Strawberry Lime | C31: 1.4 | D31: 1.7 | E31: 1.9 | F31: Voldis / Comabe | J31: =SUM(G31:I31) -> 0 | K31: =SUM(C31*J31) -> 0
A32: 500 | B32: Rekordelig Can Strawberry Lime Case 24 | C32: 33.51 | D32: 38 | E32: 40 | F32: Voldis / Comabe | G32: 2 | J32: =SUM(G32:I32) -> 2 | K32: =SUM(C32*J32) -> 67.02
A33: 500 | B33: Rekordelig Can Wild Berry | C33: 1.4 | D33: 1.7 | E33: 1.9 | F33: Voldis / Comabe | J33: =SUM(G33:I33) -> 0 | K33: =SUM(C33*J33) -> 0
A34: 500 | B34: Rekordelig Can Wild Berry Case 24 | C34: 33.51 | D34: 38 | E34: 40 | F34: Voldis / Comabe | J34: =SUM(G34:I34) -> 0 | K34: =SUM(C34*J34) -> 0
A35: 500 | B35: Rekordelig Can Mango & Raspberry | C35: 1.4 | D35: 1.7 | E35: 1.9 | F35: Voldis / Comabe | J35: =SUM(G35:I35) -> 0 | K35: =SUM(C35*J35) -> 0
A36: 500 | B36: Rekordelig Can Mango & Raspberry Case 24 | C36: 33.51 | D36: 38 | E36: 40 | F36: Voldis / Comabe | J36: =SUM(G36:I36) -> 0 | K36: =SUM(C36*J36) -> 0
A38: 500 | B38: Strongbow Can | C38: 1.17 | D38: 1.5 | E38: 1.6 | F38: TransMallorca / Tunel | J38: =SUM(G38:I38) -> 0 | K38: =SUM(C38*J38) -> 0
A39: 500 | B39: Strongbow Can Case 24 | C39: 28.08 | D39: 32 | E39: 34 | F39: TransMallorca / Tunel | I39: 2 | J39: =SUM(G39:I39) -> 2 | K39: =SUM(C39*J39) -> 56.16
A41: 500 | B41: Thatchers Can | C41: 1.7 | D41: 1.95 | E41: 2.25 | F41: Tunel | J41: =SUM(G41:I41) -> 0 | K41: =SUM(C41*J41) -> 0
A42: 500 | B42: Thatchers Can Case 24 | C42: 40.85 | D42: 45 | E42: 48 | F42: Tunel | I42: 1 | J42: =SUM(G42:I42) -> 1 | K42: =SUM(C42*J42) -> 40.85

Sheet Alco Pops
A1: Cap. (ml) | B1: Item | C1: Buy 2025 | D1: Bar Price | E1: Shop Price | F1: Supplier | G1: Downstairs/Out back | H1: Shelves | I1: Storage Upstairs | J1: Quantity | K1: Value
K2: =SUM(K3:K103) -> 917.97
B3: Alco-Pops
A5: 275 | B5: Smirnoff Ice Case 24 | C5: 31.15 | D5: 38 | E5: 40 | F5: Tunel | I5: 3 | J5: =SUM(G5:I5) -> 3 | K5: =SUM(C5*J5) -> 93.45
A6: 275 | B6: Smirnoff Ice Bottle | C6: 1.3 | D6: 1.85 | E6: 1.95 | F6: Tunel | J6: =SUM(G6:I6) -> 0 | K6: =SUM(C6*J6) -> 0
A7: 700 | B7: Smirnoff Ice Bottle | C7: 3.37 | D7: 4.95 | E7: 4.95 | F7: Tunel | I7: . | J7: =SUM(G7:I7) -> 0 | K7: =SUM(C7*J7) -> 0
A8: 700 | B8: Smirnoff Ice Bottle 700ml x 6 | C8: 20.26 | D8: 29 | E8: 29 | F8: Tunel | J8: =SUM(G8:I8) -> 0 | K8: =SUM(C8*J8) -> 0
A10: 275 | B10: WKD Blue Case 24 | C10: 30.4 | D10: 33 | E10: 38 | F10: Tunel | I10: 5 | J10: =SUM(G10:I10) -> 5 | K10: =SUM(C10*J10) -> 152
A11: 275 | B11: WKD Blue Bottle | C11: 1.26 | D11: 1.5 | E11: 1.95 | F11: Tunel | J11: =SUM(G11:I11) -> 0 | K11: =SUM(C11*J11) -> 0
A12: 700 | B12: WKD Blue Bottle | C12: 4.02 | D12: 4.95 | E12: 4.95 | F12: Tunel | J12: =SUM(G12:I12) -> 0 | K12: =SUM(C12*J12) -> 0
A13: 700 | B13: WKD Blue Bottle 700ml x 6 | C13: 24.12 | D13: 29 | E13: 29 | F13: Tunel | I13: 2 | J13: =SUM(G13:I13) -> 2 | K13: =SUM(C13*J13) -> 48.24
A15: 275 | B15: Bacardi Breezer Orange Case 24 | C15: 38.23 | D15: 43.5 | E15: 48 | F15: Tunel | I15: 6 | J15: =SUM(G15:I15) -> 6 | K15: =SUM(C15*J15) -> 229.38
A16: 275 | B16: Bacardi Breezer Orange Bottle | C16: 1.59 | D16: 1.95 | E16: 2.25 | F16: Tunel | J16: =SUM(G16:I16) -> 0 | K16: =SUM(C16*J16) -> 0
A17: 275 | B17: Bacardi Breezer Watermelon Case 24 | C17: 38.23 | D17: 43.5 | E17: 48 | F17: Tunel | I17: 5 | J17: =SUM(G17:I17) -> 5 | K17: =SUM(C17*J17) -> 191.15
A18: 275 | B18: Bacardi Breezer Watermelon Bottle | C18: 1.59 | D18: 1.95 | E18: 2.25 | F18: Tunel | J18: =SUM(G18:I18) -> 0 | K18: =SUM(C18*J18) -> 0
A19: 275 | B19: Bacardi Breezer Lime Case 24 | C19: 40.75 | D19: 45 | E19: 48 | F19: Tunel | I19: 5 | J19: =SUM(G19:I19) -> 5 | K19: =SUM(C19*J19) -> 203.75
A20: 275 | B20: Bacardi Breezer Lime Bottle | C20: 1.7 | D20: 1.95 | E20: 2.25 | F20: Tunel | J20: =SUM(G20:I20) -> 0 | K20: =SUM(C20*J20) -> 0
A21: 275 | B21: Bacardi Breezer Passion Fruit & Mango Case 12 | C21: 22 | D21: 24 | E21: 24 | F21: Tunel | J21: =SUM(G21:I21) -> 0 | K21: =SUM(C21*J21) -> 0
A22: 275 | B22: Bacardi Breezer Passion Fruit & Mango Bottle | C22: 1.83 | D22: 2 | E22: 2.25 | F22: Tunel | J22: =SUM(G22:I22) -> 0 | K22: =SUM(C22*J22) -> 0
B24: White Claw Hard Seltzer | C24: 1.81 | D24: 2.8 | E24: 2.8 | F24: Tunel | J24: =SUM(G24:I24) -> 0 | K24: =SUM(C24*J24) -> 0
J41: =SUM(G41:I41) -> 0 | K41: =SUM(C41*J41) -> 0
J42: =SUM(G42:I42) -> 0 | K42: =SUM(C42*J42) -> 0
J43: =SUM(G43:I43) -> 0 | K43: =SUM(C43*J43) -> 0
J44: =SUM(G44:I44) -> 0 | K44: =SUM(C44*J44) -> 0
J45: =SUM(G45:I45) -> 0 | K45: =SUM(C45*J45) -> 0
J46: =SUM(G46:I46) -> 0 | K46: =SUM(C46*J46) -> 0
J47: =SUM(G47:I47) -> 0 | K47: =SUM(C47*J47) -> 0

Sheet Soft Drinks & Mixers
A1: Cap. (ml) | B1: Item | C1: Buy 2025 | D1: Bar Price | E1: Shop Price | F1: Supplier | G1: Downstairs/Out back | H1: Shelves | I1: Storage Upstairs | J1: Quantity | K1: Value
K2: =SUM(K3:K92) -> 1390.06
B4: Cokes & Fantas
J5: =SUM(G5:I5) -> 0 | K5: =SUM(C5*J5) -> 0
A6: 2L | B6: Coke 2L | C6: 1.81 | D6: 2 | E6: 2.4 | F6: Coke | J6: =SUM(G6:I6) -> 0 | K6: =SUM(C6*J6) -> 0
A7: 330 | B7: Coke Can | C7: 0.76 | D7: 0.9 | E7: 1 | F7: Coke / HG | J7: =SUM(G7:I7) -> 0 | K7: =SUM(C7*J7) -> 0
A8: 330 | B8: Coke Can Case 24 | C8: 18.23 | D8: 19.95 | E8: 19.95 | F8: Coke / HG | I8: 11 | J8: =SUM(G8:I8) -> 11 | K8: =SUM(C8*J8) -> 200.53
A9: 500 | B9: Coke 500ml Bottle | D9: 1.3 | E9: 1.4 | F9: Coke | J9: =SUM(G9:I9) -> 0 | K9: =SUM(C9*J9) -> 0
A10: 2L | B10: Coke Light 2L | C10: 1.81 | D10: 2 | E10: 2.4 | F10: Coke | J10: =SUM(G10:I10) -> 0 | K10: =SUM(C10*J10) -> 0
A11: 330 | B11: Coke Light Can | C11: 0.76 | D11: 0.9 | E11: 1 | F11: Coke / HG | J11: =SUM(G11:I11) -> 0 | K11: =SUM(C11*J11) -> 0
A12: 330 | B12: Coke Light Can Case 24 | C12: 18.23 | D12: 19.95 | E12: 19.95 | F12: Coke / HG | I12: 5 | J12: =SUM(G12:I12) -> 5 | K12: =SUM(C12*J12) -> 91.15
A13: 330 | B13: Coke Zero Can | C13: 0.76 | D13: 0.9 | E13: 1 | F13: Coke / HG | J13: =SUM(G13:I13) -> 0 | K13: =SUM(C13*J13) -> 0
A14: 330 | B14: Coke Zero Can Case 24 | C14: 18.23 | D14: 19.95 | E14: 19.95 | F14: Coke / HG | I14: 9 | J14: =SUM(G14:I14) -> 9 | K14: =SUM(C14*J14) -> 164.07
A15: 2L | B15: Fanta Lemon 2L | C15: 1.55 | D15: 1.95 | E15: 2.4 | F15: Coke | J15: =SUM(G15:I15) -> 0 | K15: =SUM(C15*J15) -> 0
A16: 330 | B16: Fanta Lemon Zero Can | C16: 0.73 | D16: 0.9 | E16: 1 | F16: Coke | J16: =SUM(G16:I16) -> 0 | K16: =SUM(C16*J16) -> 0
A17: 330 | B17: Fanta Lemon Zero Can Case 24 | C17: 17.37 | D17: 18.95 | E17: 19.95 | F17: Coke | I17: 1 | J17: =SUM(G17:I17) -> 1 | K17: =SUM(C17*J17) -> 17.37
A18: 330 | B18: Fanta Lemon Can | C18: 0.73 | D18: 0.9 | E18: 1 | F18: Coke / HG | J18: =SUM(G18:I18) -> 0 | K18: =SUM(C18*J18) -> 0
A19: 330 | B19: Fanta Lemon Can Case 24 | C19: 17.37 | D19: 18.95 | E19: 19.95 | F19: Coke / HG | I19: 6 | J19: =SUM(G19:I19) -> 6 | K19: =SUM(C19*J19) -> 104.22
A20: 2L | B20: Fanta Orange 2L | C20: 1.55 | D20: 1.95 | E20: 2.4 | F20: Coke | J20: =SUM(G20:I20) -> 0 | K20: =SUM(C20*J20) -> 0
A21: 330 | B21: Fanta Orange Zero Can | C21: 0.73 | D21: 0.9 | E21: 1 | F21: Coke | J21: =SUM(G21:I21) -> 0 | K21: =SUM(C21*J21) -> 0
A22: 330 | B22: Fanta Orange Zero Can Case 24 | C22: 17.37 | D22: 18.95 | E22: 19.95 | F22: Coke | I22: 0 | J22: =SUM(G22:I22) -> 0 | K22: =SUM(C22*J22) -> 0
A23: 330 | B23: Fanta Orange Can | C23: 0.73 | D23: 0.9 | E23: 1 | F23: Coke / HG | J23: =SUM(G23:I23) -> 0 | K23: =SUM(C23*J23) -> 0
A24: 330 | B24: Fanta Orange Can Case 24 | C24: 17.37 | D24: 18.95 | E24: 19.95 | F24: Coke / HG | I24: 5 | J24: =SUM(G24:I24) -> 5 | K24: =SUM(C24*J24) -> 86.85
A25: 330 | B25: Nestea Case 24 | C25: 16.84 | D25: 20 | E25: 22 | F25: Comabe | I25: 2 | J25: =SUM(G25:I25) -> 2 | K25: =SUM(C25*J25) -> 33.68
A26: 330 | B26: Nestea Can | C26: 0.7 | D26: 0.9 | E26: 0.9 | F26: Comabe | J26: =SUM(G26:I26) -> 0 | K26: =SUM(C26*J26) -> 0
A27: 2L | B27: Sprite 2L | C27: 1.77 | D27: 2 | E27: 2.4 | F27: Coke | J27: =SUM(G27:I27) -> 0 | K27: =SUM(C27*J27) -> 0
A28: 330 | B28: Sprite Can | C28: 0.73 | D28: 0.9 | E28: 1 | F28: Coke / HG | J28: =SUM(G28:I28) -> 0 | K28: =SUM(C28*J28) -> 0
A29: 330 | B29: Sprite Can Case 24 | C29: 17.37 | D29: 18.95 | E29: 19.95 | F29: Coke / HG | I29: 7 | J29: =SUM(G29:I29) -> 7 | K29: =SUM(C29*J29) -> 121.59
A30: 330 | B30: Sprite Zero Can | C30: 0.73 | D30: 0.9 | E30: 1 | F30: Coke | J30: =SUM(G30:I30) -> 0 | K30: =SUM(C30*J30) -> 0
A31: 330 | B31: Sprite Zero Can Case 24 | C31: 17.37 | D31: 18.95 | E31: 19.95 | F31: Coke | I31: 3 | J31: =SUM(G31:I31) -> 3 | K31: =SUM(C31*J31) -> 52.11
B33: Irn Bru
A35: 330 | B35: Irn Bru Can | C35: 0.71 | D35: 0.9 | E35: 0.95 | F35: Interbalear | J35: =SUM(G35:I35) -> 0 | K35: =SUM(C35*J35) -> 0
A36: 330 | B36: Irn Bru Can Case 24 | C36: 17.04 | D36: 19.95 | E36: 21 | F36: Interbalear | I36: 3 | J36: =SUM(G36:I36) -> 3 | K36: =SUM(C36*J36) -> 51.12
A37: 330 | B37: Irn Bru Diet Can | C37: 0.71 | D37: 0.9 | E37: 0.95 | F37: Interbalear | J37: =SUM(G37:I37) -> 0 | K37: =SUM(C37*J37) -> 0
A38: 330 | B38: Irn Bru Diet Can Case 24 | C38: 17.04 | D38: 19.95 | E38: 21 | F38: Interbalear | I38: 1 | J38: =SUM(G38:I38) -> 1 | K38: =SUM(C38*J38) -> 17.04
B40: Tonics/Soda etc.
B42: Fevertree Tonic 24x250ml CAN | C42: 17.9 | D42: 21 | E42: 22 | F42: Comabe | J42: =SUM(G42:I42) -> 0 | K42: =SUM(C42*J42) -> 0
B43: Fevertree Tonic 250ml CAN | C43: 0.75 | D43: 0.9 | E43: 0.95 | F43: Comabe | J43: =SUM(G43:I43) -> 0 | K43: =SUM(C43*J43) -> 0
B44: Fevertree Tonic 24x200 | C44: 23.95 | D44: 29 | E44: 30 | F44: Comabe | I44: 5 | J44: =SUM(G44:I44) -> 5 | K44: =SUM(C44*J44) -> 119.75
B45: Fevertree Tonic 4x200 | C45: 4 | D45: 5 | E45: 5 | F45: Comabe | J45: =SUM(G45:I45) -> 0 | K45: =SUM(C45*J45) -> 0
...

Sheet Frozen Food
A1: Item | B1: Cap. (g) | C1: Buy 2025 | D1: Bar Price | E1: Shop Price | F1: Supplier | G1: Downstairs/Out back | H1: Shelves | I1: Storage Upstairs | J1: Quantity | K1: Value
A2: Frozen Goods | K2: =SUM(K3:K90) -> 359.57
A4: Pies
A6: Chicken & Mushroom Pie | C6: 2.31 | D6: 2.8 | E6: 3 | F6: Europ Foods | H6: 19 | J6: =SUM(G6:I6) -> 19 | K6: =SUM(C6*J6) -> 43.89
A7: Mince Meat & Onion Pie | C7: 2.21 | D7: 2.8 | E7: 3 | F7: Europ Foods | H7: 7 | J7: =SUM(G7:I7) -> 7 | K7: =SUM(C7*J7) -> 15.47
A8: Steak & Guinness Pie | C8: 2.75 | D8: 3 | E8: 3 | F8: Europ Foods | H8: 10 | J8: =SUM(G8:I8) -> 10 | K8: =SUM(C8*J8) -> 27.5
A9: Steak & Kidney Pie | C9: 2.39 | D9: 2.8 | E9: 3 | F9: Europ Foods | H9: 10 | J9: =SUM(G9:I9) -> 10 | K9: =SUM(C9*J9) -> 23.9
A10: Steak Pie | C10: 2.47 | D10: 2.8 | E10: 3 | F10: Europ Foods | H10: 17 | J10: =SUM(G10:I10) -> 17 | K10: =SUM(C10*J10) -> 41.99
A11: Meat & Potato Pie | C11: 2.08 | D11: 2.8 | E11: 3 | F11: Europ Foods | H11: 10 | J11: =SUM(G11:I11) -> 10 | K11: =SUM(C11*J11) -> 20.8
A12: Cornish Pastie | C12: 1.99 | D12: 2.2 | E12: 2.2 | F12: Europ Foods | H12: 6 | J12: =SUM(G12:I12) -> 6 | K12: =SUM(C12*J12) -> 11.94
A13: Cheese & Onion Pastie | C13: 1.66 | D13: 2.2 | E13: 2.2 | F13: Europ Foods | H13: 12 | J13: =SUM(G13:I13) -> 12 | K13: =SUM(C13*J13) -> 19.92
A14: Sausage Roll Jumbo | C14: 1.75 | D14: 2.2 | E14: 2.2 | F14: Europ Foods | H14: 5 | J14: =SUM(G14:I14) -> 5 | K14: =SUM(C14*J14) -> 8.75
A17: Frozen Meat
A19: Bacon 2.25kg | C19: 17.71 | D19: 20 | E19: 20 | F19: Europ Foods | H19: 1 | J19: =SUM(G19:I19) -> 1 | K19: =SUM(C19*J19) -> 17.71
A20: Bacon 400g | C20: 3.46 | D20: 4.5 | E20: 4.5 | F20: Europ Foods | H20: 5 | J20: =SUM(G20:I20) -> 5 | K20: =SUM(C20*J20) -> 17.3
A21: Bacon 200g | C21: 1.82 | D21: 2.75 | E21: 2.75 | F21: Europ Foods | J21: =SUM(G21:I21) -> 0 | K21: =SUM(C21*J21) -> 0
A22: Sausage Bag 40 | C22: 11.5 | D22: 12.95 | E22: 12.95 | F22: Europ Foods | H22: 2 | J22: =SUM(G22:I22) -> 2 | K22: =SUM(C22*J22) -> 23
A23: Sausage Individual | C23: 0.29 | D23: 0.4 | E23: 0.4 | F23: Europ Foods | J23: =SUM(G23:I23) -> 0 | K23: =SUM(C23*J23) -> 0
A24: Lorne Sausage 1Kg bag | C24: 8.2 | D24: 9.95 | E24: 9.95 | F24: Europ Foods | H24: 1 | J24: =SUM(G24:I24) -> 1 | K24: =SUM(C24*J24) -> 8.2
A25: Black Pudding Single | D25: 0.4 | E25: 0.4 | F25: Europ Foods | J25: =SUM(G25:I25) -> 0 | K25: =SUM(C25*J25) -> 0
A26: Black Pudding Stick 1.36Kg | C26: 5.94 | D26: 7 | E26: 7 | F26: Europ Foods | J26: =SUM(G26:I26) -> 0 | K26: =SUM(C26*J26) -> 0
A27: Gammon Joint per Kg | C27: 7.13 | D27: 7.90 per kg | E27: 7.90 per kg | F27: Europ Foods | J27: =SUM(G27:I27) -> 0 | K27: =SUM(C27*J27) -> 0
A28: Gammon Steak Pack 2 | C28: 5.22 | D28: 6.5 | E28: 6.5 | F28: Europ Foods | H28: 2 | J28: =SUM(G28:I28) -> 2 | K28: =SUM(C28*J28) -> 10.44
A29: Irish Steak Burger | C29: 1.2 | D29: 1.5 | E29: 1.5 | F29: Europ Foods | J29: =SUM(G29:I29) -> 0 | K29: =SUM(C29*J29) -> 0
A30: Haggis | C30: 6.38 | D30: 7 | E30: 7 | F30: Europ Foods | J30: =SUM(G30:I30) -> 0 | K30: =SUM(C30*J30) -> 0
A31: Chicken Kiev Bag 5 | C31: 12.3 | D31: 14 | E31: 14 | F31: Europ Foods | H31: 1 | J31: =SUM(G31:I31) -> 1 | K31: =SUM(C31*J31) -> 12.3
A32: Chicken Kiev Single | C32: 2.46 | D32: 2.8 | E32: 2.8 | F32: Europ Foods | J32: =SUM(G32:I32) -> 0 | K32: =SUM(C32*J32) -> 0
A33: Spicy Chicken Wings Bag 48 | C33: 22.82 | D33: 24 | E33: 24 | F33: Europ Foods | J33: =SUM(G33:I33) -> 0 | K33: =SUM(C33*J33) -> 0
A34: Spicy Chicken Wings Single | C34: 0.47 | D34: 0.6 | E34: 0.6 | F34: Europ Foods | J34: =SUM(G34:I34) -> 0 | K34: =SUM(C34*J34) -> 0
A35: Southern Fried Chicken Goujon Strip Bag | C35: 12.37 | D35: 14 | E35: 14 | F35: Europ Foods | J35: =SUM(G35:I35) -> 0 | K35: =SUM(C35*J35) -> 0
A36: Pork Pies Pack 4 | C36: 3.36 | D36: 4 | E36: 4 | F36: Tindale | J36: =SUM(G36:I36) -> 0 | K36: =SUM(C36*J36) -> 0
A39: Bread / Cake
A41: Thick Bread | C41: 2.7 | D41: 3.3 | E41: 3.3 | F41: Europ Foods | H41: 6 | J41: =SUM(G41:I41) -> 6 | K41: =SUM(C41*J41) -> 16.2
A42: Medium Bread | C42: 2.7 | D42: 3.3 | E42: 3.3 | F42: Europ Foods | J42: =SUM(G42:I42) -> 0 | K42: =SUM(C42*J42) -> 0
A43: Wholemeal Bread | C43: 2.7 | D43: 3.3 | E43: 3.3 | F43: Europ Foods | J43: =SUM(G43:I43) -> 0 | K43: =SUM(C43*J43) -> 0
A44: Malted Wholegrain | C44: 2.7 | D44: 3.3 | E44: 3.3 | F44: Europ Foods | J44: =SUM(G44:I44) -> 0 | K44: =SUM(C44*J44) -> 0
A45: Dutch Baps Pack 8 | C45: 3.73 | D45: 4.5 | E45: 4.5 | F45: Europ Foods | H45: 4 | J45: =SUM(G45:I45) -> 4 | K45: =SUM(C45*J45) -> 14.92
A46: Tea Cakes Pack 5 | C46: 3.62 | D46: 4.5 | E46: 4.5 | F46: Europ Foods | H46: 6 | J46: =SUM(G46:I46) -> 6 | K46: =SUM(C46*J46) -> 21.72
A47: Crumpets Pack 6 | C47: 1.81 | D47: 2.5 | E47: 2.5 | F47: Europ Foods | H47: 2 | J47: =SUM(G47:I47) -> 2 | K47: =SUM(C47*J47) -> 3.62
A48: Muffins Pack 4 | C48: 2.15 | D48: 3 | E48: 3 | F48: Europ Foods | J48: =SUM(G48:I48) -> 0 | K48: =SUM(C48*J48) -> 0
...

Sheet Dried Food
A1: Item | B1: Cap. (g) | C1: Buy 2025 | D1: Bar Price | E1: Shop Price | F1: Supplier | G1: Downstairs/Out back | H1: Shelves | I1: Storage Upstairs | J1: Quantity | K1: Value
A2: Dried Goods | K2: =SUM(K3:K103) -> 0
A4: Beans | E4: 1.75 | F4: Interbalear
A5: Branston Pickle | E5: 3.9 | F5: Interbalear | J5: =SUM(G5:I5) -> 0 | K5: =SUM(C5*J5) -> 0
A6: Colmans Mustard | D6: 2.8 | E6: 2.8 | F6: Interbalear | J6: =SUM(G6:I6) -> 0 | K6: =SUM(C6*J6) -> 0
A7: Corned Beef | C7: 3.8 | D7: 4.8 | E7: 4.8 | F7: Interbalear | J7: =SUM(G7:I7) -> 0 | K7: =SUM(C7*J7) -> 0
A8: Crackers | B8: 240g | C8: 1.66 | D8: 2.4 | E8: 2.4 | F8: Interbalear | J8: =SUM(G8:I8) -> 0 | K8: =SUM(C8*J8) -> 0
A9: Gravy | C9: 2.54 | D9: 3 | E9: 3 | F9: Tindale | J9: =SUM(G9:I9) -> 0 | K9: =SUM(C9*J9) -> 0
A10: Heinz Ketchup | E10: 3 | F10: Interbalear | J10: =SUM(G10:I10) -> 0 | K10: =SUM(C10*J10) -> 0
A11: HP Sauce | C11: 1.77 | E11: 2.8 | F11: Interbalear | J11: =SUM(G11:I11) -> 0 | K11: =SUM(C11*J11) -> 0
A12: Lea & Perrins | D12: 4.5 | E12: 4.5 | F12: Interbalear | J12: =SUM(G12:I12) -> 0 | K12: =SUM(C12*J12) -> 0
A13: Mint Sauce | E13: 2.8 | F13: Interbalear | J13: =SUM(G13:I13) -> 0 | K13: =SUM(C13*J13) -> 0
A14: Mushy Peas | E14: 1.3 | F14: Interbalear | J14: =SUM(G14:I14) -> 0 | K14: =SUM(C14*J14) -> 0
A15: Pot Noodle | D15: 1.95 | E15: 1.95 | F15: Interbalear | J15: =SUM(G15:I15) -> 0 | K15: =SUM(C15*J15) -> 0
A16: Sarsons Vinegar | D16: 3 | E16: 3 | F16: Interbalear | J16: =SUM(G16:I16) -> 0 | K16: =SUM(C16*J16) -> 0
A17: Soup Chicken | D17: 1.8 | E17: 1.8 | F17: Interbalear | J17: =SUM(G17:I17) -> 0 | K17: =SUM(C17*J17) -> 0
A18: Soup Tomato | D18: 1.8 | E18: 1.8 | F18: Interbalear | J18: =SUM(G18:I18) -> 0 | K18: =SUM(C18*J18) -> 0
A19: Tabasco | C19: 3.9 | D19: 4.5 | E19: 4.5 | F19: Interbalear | J19: =SUM(G19:I19) -> 0 | K19: =SUM(C19*J19) -> 0
A20: Tea Bags Tetley | D20: 2.4 | E20: 2.4 | F20: Interbalear | J20: =SUM(G20:I20) -> 0 | K20: =SUM(C20*J20) -> 0
J41: =SUM(G41:I41) -> 0 | K41: =SUM(C41*J41) -> 0
J42: =SUM(G42:I42) -> 0 | K42: =SUM(C42*J42) -> 0
J43: =SUM(G43:I43) -> 0 | K43: =SUM(C43*J43) -> 0
J44: =SUM(G44:I44) -> 0 | K44: =SUM(C44*J44) -> 0
J45: =SUM(G45:I45) -> 0 | K45: =SUM(C45*J45) -> 0
J46: =SUM(G46:I46) -> 0 | K46: =SUM(C46*J46) -> 0
J47: =SUM(G47:I47) -> 0 | K47: =SUM(C47*J47) -> 0

Sheet Sweets & Crisps
A1: Item | B1: Cap. (g) | C1: Buy 2025 | D1: Bar Price | E1: Shop Price | F1: Supplier | G1: Shelves | H1: Storage Upstairs | I1: Quantity | J1: Value
J2: =SUM(J3:J102) -> 0
A3: SWEETS
A5: Twirl | B5: 43 | C5: 1.27 | D5: 1.4 | E5: 1.5 | F5: Cabalsa | I5: =SUM(F5:H5) -> 0 | J5: =SUM(C5*I5) -> 0
A6: Dairy Milk | B6: 49 | C6: 1.25 | D6: 1.4 | E6: 1.5 | F6: Cabalsa | I6: =SUM(F6:H6) -> 0 | J6: =SUM(C6*I6) -> 0
A7: Whole Nut | B7: 49 | C7: 1.25 | D7: 1.4 | E7: 1.5 | F7: Cabalsa | I7: =SUM(F7:H7) -> 0 | J7: =SUM(C7*I7) -> 0
A8: Fruit & Nut | B8: 49 | C8: 1.04 | D8: 1.4 | E8: 1.5 | F8: Cabalsa | I8: =SUM(F8:H8) -> 0 | J8: =SUM(C8*I8) -> 0
A9: Crunchie | B9: 40 | C9: 1.09 | D9: 1.4 | E9: 1.5 | F9: Cabalsa | I9: =SUM(F9:H9) -> 0 | J9: =SUM(C9*I9) -> 0
A10: Caramel | B10: 50 | C10: 1.25 | D10: 1.4 | E10: 1.5 | F10: Cabalsa | I10: =SUM(F10:H10) -> 0 | J10: =SUM(C10*I10) -> 0
A12: CRISPS
A14: Walkers All Flavours Bag | B14: 32 | D14: 0.9 | E14: 1.2 | F14: Interbalear | I14: =SUM(F14:H14) -> 0 | J14: =SUM(C14*I14) -> 0
A15: Walkers All Flavours Box 32 | B15: 32 | D15: 30 | E15: 32 | F15: Interbalear | I15: =SUM(F15:H15) -> 0 | J15: =SUM(C15*I15) -> 0
A16: LAYS Big Bags | B16: 170 | C16: 1.48 | D16: 2.25 | E16: 2.25 | F16: Pepsico | I16: =SUM(F16:H16) -> 0 | J16: =SUM(C16*I16) -> 0
A20: OTHERS
A22: Golden Wonder Salted Nuts | B22: 50 | F22: Interbalear | I22: =SUM(F22:H22) -> 0 | J22: =SUM(C22*I22) -> 0
A23: KPSalted Nuts | B23: 50 | F23: Interbalear | I23: =SUM(F23:H23) -> 0 | J23: =SUM(C23*I23) -> 0
A24: Bacon Fries | B24: 25 | F24: Interbalear | I24: =SUM(F24:H24) -> 0 | J24: =SUM(C24*I24) -> 0
A25: Scampi Fries | B25: 25 | F25: Interbalear | I25: =SUM(F25:H25) -> 0 | J25: =SUM(C25*I25) -> 0
A26: Pork Scratchings | F26: Interbalear | I26: =SUM(F26:H26) -> 0 | J26: =SUM(C26*I26) -> 0
A27: Orbit Chewing Gum | F27: Rotger/GM | I27: =SUM(F27:H27) -> 0 | J27: =SUM(C27*I27) -> 0
I40: =SUM(F40:H40) -> 0 | J40: =SUM(C40*I40) -> 0
I41: =SUM(F41:H41) -> 0 | J41: =SUM(C41*I41) -> 0
I42: =SUM(F42:H42) -> 0 | J42: =SUM(C42*I42) -> 0
I43: =SUM(F43:H43) -> 0 | J43: =SUM(C43*I43) -> 0
I44: =SUM(F44:H44) -> 0 | J44: =SUM(C44*I44) -> 0
I45: =SUM(F45:H45) -> 0 | J45: =SUM(C45*I45) -> 0
I46: =SUM(F46:H46) -> 0 | J46: =SUM(C46*I46) -> 0
